Workbook

Sheet ListOfRegions
A1: 01 | B1: Ροδόπης | H1: ΑΠΟΚΕΝΤΡΩΜΕΝΗ ΔΙΟΙΚΗΣΗ ΜΑΚΕΔΟΝΙΑΣ - ΘΡΑΚΗΣ
A2: 02 | B2: Δράμας
A3: 03 | B3: Έβρου | D3: ΠΕΡΙΦΕΡΕΙΑ ΑΝΑΤΟΛΙΚΗΣ ΜΑΚΕΔΟΝΙΑΣ
A4: 04 | B4: Θάσου | D4: ΚΑΙ ΘΡΑΚΗΣ
A5: 05 | B5: Καβάλας
A6: 06 | B6: Ξάνθης
A7: 07 | B7: Θεσσαλονίκης
A8: 08 | B8: Ημαθίας
A9: 09 | B9: Κιλκίς
A10: 10 | B10: Πέλλας
A11: 11 | B11: Πιερίας | D11: ΠΕΡΙΦΕΡΕΙΑ ΚΕΝΤΡΙΚΗΣ ΜΑΚΕΔΟΝΙΑΣ
A12: 12 | B12: Σερρών
A13: 13 | B13: Χαλκιδικής
A14: 14 | B14: Κοζάνης
A15: 15 | B15: Γρεβενών
A16: 16 | B16: Καστοριάς
A17: 17 | B17: Φλώρινας
A18: 18 | B18: Ιωαννίνων
A19: 19 | B19: Άρτας
A20: 20 | B20: Θεσπρωτίας | D20: ΠΕΡΙΦΕΡΕΙΑ ΗΠΕΙΡΟΥ
A21: 21 | B21: Πρέβεζας
A22: 22 | B22: Λάρισας | H22: ΑΠΟΚΕΝΤΡΩΜΕΝΗ ΔΙΟΙΚΗΣΗ ΘΕΣΣΑΛΙΑΣ - ΣΤΕΡΕΑΣ ΕΛΛΑΔΑΣ
A23: 23 | B23: Καρδίτσας
A24: 24 | B24: Μαγνησίας | D24: ΠΕΡΙΦΕΡΕΙΑ ΘΕΣΣΑΛΙΑΣ
A25: 25 | B25: Σποράδων
A26: 26 | B26: Τρικάλων
A27: 27 | B27: Φθιώτιδας
A28: 28 | B28: Βοιωτίας
A29: 29 | B29: Εύβοιας | D29: ΠΕΡΙΦΕΡΕΙΑ ΣΤΕΡΕΑΣ ΕΛΛΑΔΑΣ
A30: 30 | B30: Ευρυτανίας
A31: 31 | B31: Φωκίδας
A32: 32 | B32: Κέρκυρας | H32: ΑΠΟΚΕΝΤΡΩΜΕΝΗ ΔΙΟΙΚΗΣΗ ΠΕΛΟΠΟΝΝΗΣΟΥ, ΔΥΤΙΚΗΣ ΕΛΛΑΔΑΣ ΚΑΙ ΙΟΝΙΟΥ
A33: 33 | B33: Ζακύνθου
A34: 34 | B34: Ιθάκης | D34: ΠΕΡΙΦΕΡΕΙΑ ΙΟΝΙΩΝ ΝΗΣΩΝ
A35: 35 | B35: Κεφαλληνίας
A36: 36 | B36: Λευκάδας
A37: 37 | B37: Αχαϊας
A38: 38 | B38: Αιτωλ/νανίας | D38: ΠΕΡΙΦΕΡΕΙΑ ΔΥΤΙΚΗΣ ΕΛΛΑΔΑΣ
A39: 39 | B39: Ηλείας
A40: 40 | B40: Αρκαδίας
...

Sheet Πίνακας2(α)
A1: 2. Αροτραίες καλλιέργειες | G1: 2. Crops on arable land | M1: Πίνακας 2α. Συνέχεια | Q1: Table 2a. Continued
A2: 2α. Σιτηρά για καρπό. Εκτάσεις και παραγωγή κατά Περιφέρεια και Περιφερειακή Ενότητα. Έτος 2011 | G2: Table 2a. Cereals for grain. Areas and production, by Region and Regional Unity. Year 2011
A3: Εκτάσεις σε στρέμματα, παραγωγή σε τόνους | G3: Areas in stremmas, production in tons | M3: Εκτάσεις σε στρέμματα, παραγωγή σε τόνους | Q3: Areas in stremmas, production in tons
A4: Περιφέρειες και Περιφερειακές Ενότητες | B4: Σύνολο Εκτάσεων - Total Area | C4: Σιτάρι Wheat | G4: Κριθάρι Barley | I4: Βρώμη Oats | K4: Σίκαλη Rye | M4: Αραβόσιτος - Maize | Q4: Ρύζι Rice | S4: Σόργο Sorghum | U4: Λοιπά(1) Other | W4: Regions and Regional Unities (NUTS 2)
C6: Μαλακό Soft | E6: Σκληρό Hard | M6: χωρίς συγκαλλιέργεια grown alone | O6: συγκαλλιεργούμενος με φασόλια και άλλα είδη grown with beans and other crops
C7: 1 | D7: 2 | E7: 1 | F7: 2 | G7: 1 | H7: 2 | I7: 1 | J7: 2 | K7: 1 | L7: 2 | M7: 1 | N7: 2 | O7: 1 | P7: 2 | Q7: 1 | R7: 2 | S7: 1 | T7: 2 | U7: 1 | V7: 2
A8: Σύνολο Ελλάδας | B8: 11160912 | C8: 1563268 | D8: 441474.82 | E8: 5314956 | F8: 1415954 | G8: 1211678 | H8: 319002.76 | I8: 450537 | J8: 92519.414 | K8: 139552 | L8: 32156.325 | M8: 2125441 | N8: 2286898.1 | O8: 15048 | P8: 4907.589 | Q8: 309161 | R8: 250684.91 | S8: 568 | T8: 135.1 | U8: 30703 | V8: 6795.975 | W8: Greece Total
A10: Περιφέρεια Ανατολικής Μακεδονίας και Θράκης | B10: 1622152 | C10: 329694 | D10: 104655.48 | E10: 574966 | F10: 164620.2 | G10: 119346 | H10: 32610.215 | I10: 6405 | J10: 1208.845 | K10: 6683 | L10: 1282.19 | M10: 560757 | N10: 605105.86 | O10: 0 | P10: 0 | Q10: 22209 | R10: 15813.36 | S10: 80 | T10: 12.5 | U10: 2012 | V10: 553.34 | W10: Region of Eastern Macedonia and Thrace
A12: =VLOOKUP(ListOfRegions!$A$1,ListOfRegions!$A$1:B75,2,0) -> Ροδόπης | B12: 238821 | C12: 57290 | D12: 17691.3 | E12: 112912 | F12: 32775.25 | G12: 40263 | H12: 11152.505 | I12: 1520 | J12: 223.3 | K12: 1735 | L12: 229.1 | M12: 24471 | N12: 26558.85 | O12: ― | P12: ― | Q12: ― | R12: ― | S12: ― | T12: ― | U12: 630 | V12: 130.6 | W12: Rodopi
A13: =VLOOKUP(ListOfRegions!$A$2,ListOfRegions!$A$2:B76,2,0) -> Δράμας | B13: 331944 | C13: 54474 | D13: 14542.03 | E13: 106352 | F13: 26733.835 | G13: 31993 | H13: 8346.75 | I13: 4055 | J13: 796.1 | K13: 947 | L13: 152.8 | M13: 134108 | N13: 146769.95 | O13: ― | P13: ― | Q13: ― | R13: ― | S13: ― | T13: ― | U13: 15 | V13: 3.5 | W13: Drama
A14: =VLOOKUP(ListOfRegions!A3,ListOfRegions!A3:B77,2,0) -> Έβρου | B14: 543382 | C14: 130573 | D14: 46357.07 | E14: 311667 | F14: 93492.38 | G14: 32325 | H14: 9182.58 | I14: 529 | J14: 136.08 | K14: 2817 | L14: 735.42 | M14: 62320 | N14: 71069 | O14: ― | P14: ― | Q14: 1809 | R14: 736.86 | S14: ― | T14: ― | U14: 1342 | V14: 412.99 | W14: Evros
A15: =VLOOKUP(ListOfRegions!A4,ListOfRegions!A4:B78,2,0) -> Θάσου | B15: 25 | C15: ― | D15: ― | E15: ― | F15: ― | G15: ― | H15: ― | I15: ― | J15: ― | K15: ― | L15: ― | M15: 25 | N15: 19.5 | O15: ― | P15: ― | Q15: ― | R15: ― | S15: ― | T15: ― | U15: ― | V15: ― | W15: Thasos
A16: =VLOOKUP(ListOfRegions!A5,ListOfRegions!A5:B79,2,0) -> Καβάλας | B16: 265095 | C16: 23236 | D16: 6965.07 | E16: 13662 | F16: 3380.77 | G16: 5666 | H16: 1261.23 | I16: 301 | J16: 53.365 | K16: 228 | L16: 40.74 | M16: 201497 | N16: 206730.25 | O16: ― | P16: ― | Q16: 20400 | R16: 15076.5 | S16: 80 | T16: 12.5 | U16: 25 | V16: 6.25 | W16: Kavala
A17: =VLOOKUP(ListOfRegions!A6,ListOfRegions!A6:B80,2,0) -> Ξάνθης | B17: 242885 | C17: 64121 | D17: 19100.01 | E17: 30373 | F17: 8237.97 | G17: 9099 | H17: 2667.15 | I17: ― | J17: ― | K17: 956 | L17: 124.13 | M17: 138336 | N17: 153958.31 | O17: ― | P17: ― | Q17: ― | R17: ― | S17: ― | T17: ― | U17: ― | V17: ― | W17: Xanthi
A18: Περιφέρεια Κεντρικής Μακεδονίας | B18: 4875406 | C18: 956870 | D18: 260134.51 | E18: 2327413 | F18: 530368.47 | G18: 459113 | H18: 132913.31 | I18: 53102 | J18: 10509.9 | K18: 113899 | L18: 26505.32 | M18: 678133 | N18: 742792.7 | O18: 447 | P18: 322.2 | Q18: 262267 | R18: 218620.25 | S18: 90 | T18: 9 | U18: 24072 | V18: 4894.75 | W18: Region of Central Macedonia
A20: =VLOOKUP(ListOfRegions!A7,ListOfRegions!A7:B81,2,0) -> Θεσσαλονίκης | B20: 810889 | C20: 126283 | D20: 32531.62 | E20: 347152 | F20: 80843.175 | G20: 66008 | H20: 17337.6 | I20: 16557 | J20: 3315.44 | K20: 10582 | L20: 2178.965 | M20: 46312 | N20: 49493.75 | O20: ― | P20: ― | Q20: 192135 | R20: 175351.9 | S20: 90 | T20: 9 | U20: 5770 | V20: 1387.5 | W20: Thessaloniki
A21: =VLOOKUP(ListOfRegions!A8,ListOfRegions!A8:B82,2,0) -> Ημαθίας | B21: 155630 | C21: 12912 | D21: 4983.57 | E21: 53172 | F21: 16904.49 | G21: 8280 | H21: 2848.5 | I21: 55 | J21: 14 | K21: 220 | L21: 83 | M21: 62681 | N21: 60790 | O21: 250 | P21: 200 | Q21: 18060 | R21: 10946.75 | S21: ― | T21: ― | U21: ― | V21: ― | W21: Imathia
A22: =VLOOKUP(ListOfRegions!A9,ListOfRegions!A9:B83,2,0) -> Κιλκίς | B22: 716826 | C22: 133744 | D22: 25638.275 | E22: 503163 | F22: 82623.058 | G22: 27298 | H22: 4586.29 | I22: 3127 | J22: 480.86 | K22: 3386 | L22: 474.54 | M22: 37869 | N22: 34428.619 | O22: ― | P22: ― | Q22: ― | R22: ― | S22: ― | T22: ― | U22: 8239 | V22: 1271.16 | W22: Kilkis
A23: =VLOOKUP(ListOfRegions!A10,ListOfRegions!A10:B84,2,0) -> Πέλλας | B23: 264721 | C23: 27262 | D23: 7583.655 | E23: 91192 | F23: 29907.82 | G23: 35892 | H23: 12095.025 | I23: 2090 | J23: 473.25 | K23: 1495 | L23: 329.025 | M23: 104039 | N23: 107376.18 | O23: 70 | P23: 42 | Q23: 2381 | R23: 2132.9 | S23: ― | T23: ― | U23: 300 | V23: 117 | W23: Pella
A24: =VLOOKUP(ListOfRegions!A11,ListOfRegions!A11:B85,2,0) -> Πιερίας | B24: 250304 | C24: 55769 | D24: 18797.168 | E24: 124982 | F24: 35389.293 | G24: 22588 | H24: 7091.351 | I24: 4366 | J24: 1126.88 | K24: 200 | L24: 53.1 | M24: 31599 | N24: 37087.27 | O24: ― | P24: ― | Q24: 10800 | R24: 8640 | S24: ― | T24: ― | U24: ― | V24: ― | W24: Pieria
A25: =VLOOKUP(ListOfRegions!A12,ListOfRegions!A12:B86,2,0) -> Σερρών | B25: 876299 | C25: 63416 | D25: 17572.521 | E25: 481626 | F25: 117345.15 | G25: 50985 | H25: 14827.376 | I25: 135 | J25: 35.8 | K25: 1820 | L25: 423.65 | M25: 238626 | N25: 264303.94 | O25: ― | P25: ― | Q25: 38891 | R25: 21548.7 | S25: ― | T25: ― | U25: 800 | V25: 200 | W25: Serres
A26: =VLOOKUP(ListOfRegions!A13,ListOfRegions!A13:B87,2,0) -> Χαλκιδικής | B26: 383120 | C26: 42550 | D26: 9231.69 | E26: 294310 | F26: 61231.82 | G26: 20841 | H26: 4952.53 | I26: 18058 | J26: 3267.91 | K26: 896 | L26: 149.7 | M26: 3047 | N26: 2475.37 | O26: 10 | P26: 2 | Q26: ― | R26: ― | S26: ― | T26: ― | U26: 3408 | V26: 681.6 | W26: Chalkidiki
A27: =VLOOKUP(ListOfRegions!A14,ListOfRegions!A14:B88,2,0) -> Κοζάνης | B27: 683659 | C27: 174208 | D27: 53985.458 | E27: 350294 | F27: 85873.875 | G27: 76097 | H27: 24909.015 | I27: 4175 | J27: 852.45 | K27: 18734 | L27: 3960.701 | M27: 59608 | N27: 68586.75 | O27: 9 | P27: 2.4 | Q27: ― | R27: ― | S27: ― | T27: ― | U27: 534 | V27: 68 | W27: Kozani
A28: =VLOOKUP(ListOfRegions!A15,ListOfRegions!A15:B89,2,0) -> Γρεβενών | B28: 277518 | C28: 182154 | D28: 53927.64 | E28: 14187 | F28: 3920.57 | G28: 59750 | H28: 19153.69 | I28: 3582 | J28: 733.81 | K28: 1404 | L28: 232.37 | M28: 13855 | N28: 15576.19 | O28: ― | P28: ― | Q28: ― | R28: ― | S28: ― | T28: ― | U28: 2586 | V28: 640.14 | W28: Grevena
A29: =VLOOKUP(ListOfRegions!A16,ListOfRegions!A16:B90,2,0) -> Καστοριάς | B29: 182503 | C29: 93664 | D29: 23325.35 | E29: 38390 | F29: 9537.12 | G29: 21482 | H29: 5870.42 | I29: 658 | J29: 139.5 | K29: 14361 | L29: 3210.03 | M29: 13640 | N29: 13604.5 | O29: 108 | P29: 75.8 | Q29: ― | R29: ― | S29: ― | T29: ― | U29: 200 | V29: 60 | W29: Kastoria
A30: =VLOOKUP(ListOfRegions!A17,ListOfRegions!A17:B91,2,0) -> Φλώρινας | B30: 273937 | C30: 44908 | D30: 12557.558 | E30: 28945 | F30: 6792.1 | G30: 69892 | H30: 19241.51 | I30: 299 | J30: 70 | K30: 60801 | L30: 15410.239 | M30: 66857 | N30: 89070.14 | O30: ― | P30: ― | Q30: ― | R30: ― | S30: ― | T30: ― | U30: 2235 | V30: 469.35 | W30: Florina
A31: Περιφέρεια Ηπείρου | B31: 166733 | C31: 4359 | D31: 1053.26 | E31: 1342 | F31: 277.75 | G31: 8211 | H31: 1874.859 | I31: 17925 | J31: 4465.31 | K31: 9676 | L31: 2374.317 | M31: 120228 | N31: 117760.07 | O31: 1412 | P31: 514.38 | Q31: 2970 | R31: 2280 | S31: 80 | T31: 10.9 | U31: 530 | V31: 400 | W31: Region of Epirus
A33: =VLOOKUP(ListOfRegions!A18,ListOfRegions!A18:B92,2,0) -> Ιωαννίνων | B33: 61313 | C33: 3251 | D33: 846.71 | E33: 360 | F33: 70.85 | G33: 5516 | H33: 1319.609 | I33: 1743 | J33: 341.95 | K33: 8941 | L33: 2121.657 | M33: 40822 | N33: 37608.015 | O33: 665 | P33: 254.08 | Q33: ― | R33: ― | S33: 10 | T33: 2.9 | U33: 5 | V33: 5 | W33: Ionnina
A34: =VLOOKUP(ListOfRegions!A19,ListOfRegions!A19:B93,2,0) -> Άρτας | B34: 28137 | C34: 1028 | D34: 193.1 | E34: 625 | F34: 128.2 | G34: 1293 | H34: 273.55 | I34: 3789 | J34: 868.38 | K34: 15 | L34: 2.66 | M34: 19454 | N34: 17047.5 | O34: 738 | P34: 251.6 | Q34: 670 | R34: 335 | S34: ― | T34: ― | U34: 525 | V34: 395 | W34: Arta
A35: =VLOOKUP(ListOfRegions!A20,ListOfRegions!A20:B94,2,0) -> Θεσπρωτίας | B35: 23337 | C35: 4 | D35: 1.2 | E35: 12 | F35: 2.6 | G35: 602 | H35: 130.05 | I35: 3130 | J35: 679.5 | K35: 240 | L35: 32 | M35: 17045 | N35: 17327.15 | O35: 4 | P35: 0.7 | Q35: 2300 | R35: 1945 | S35: ― | T35: ― | U35: ― | V35: ― | W35: Thesprotia
A36: =VLOOKUP(ListOfRegions!A21,ListOfRegions!A21:B95,2,0) -> Πρέβεζας | B36: 53946 | C36: 76 | D36: 12.25 | E36: 345 | F36: 76.1 | G36: 800 | H36: 151.65 | I36: 9263 | J36: 2575.48 | K36: 480 | L36: 218 | M36: 42907 | N36: 45777.4 | O36: 5 | P36: 8 | Q36: ― | R36: ― | S36: 70 | T36: 8 | U36: ― | V36: ― | W36: Preveza
A37: Περιφέρεια Θεσσαλίας | B37: 2056391 | C37: 193818 | D37: 56312.581 | E37: 1302881 | F37: 421100.38 | G37: 238031 | H37: 74997.438 | I37: 33694 | J37: 8262.037 | K37: 7516 | L37: 1599.588 | M37: 276340 | N37: 328062.44 | O37: 315 | P37: 73.6 | Q37: 0 | R37: 0 | S37: 110 | T37: 71.6 | U37: 3686 | V37: 883.74 | W37: Region of Thessally
A39: =VLOOKUP(ListOfRegions!A22,ListOfRegions!A22:B96,2,0) -> Λάρισας | B39: 1277687 | C39: 128257 | D39: 37411.252 | E39: 853211 | F39: 291687.93 | G39: 156134 | H39: 52911.705 | I39: 18171 | J39: 4550.032 | K39: 7230 | L39: 1559 | M39: 111087 | N39: 138163.5 | O39: 107 | P39: 32.1 | Q39: ― | R39: ― | S39: 110 | T39: 71.6 | U39: 3380 | V39: 823 | W39: Larissa
A40: =VLOOKUP(ListOfRegions!A23,ListOfRegions!A23:B97,2,0) -> Καρδίτσας | B40: 304688 | C40: 18528 | D40: 5263.75 | E40: 217971 | F40: 72370.97 | G40: 8181 | H40: 2359.3 | I40: 6650 | J40: 1719.6 | K40: 30 | L40: 4.5 | M40: 53166 | N40: 54252.45 | O40: 162 | P40: 29 | Q40: ― | R40: ― | S40: ― | T40: ― | U40: ― | V40: ― | W40: Karditsa
A41: =VLOOKUP(ListOfRegions!A24,ListOfRegions!A24:B98,2,0) -> Μαγνησίας | B41: 269955 | C41: 16568 | D41: 5429.46 | E41: 182233 | F41: 43926.8 | G41: 55638 | H41: 14912.1 | I41: 3820 | J41: 994.7 | K41: 100 | L41: 16 | M41: 11596 | N41: 16657.2 | O41: ― | P41: ― | Q41: ― | R41: ― | S41: ― | T41: ― | U41: ― | V41: ― | W41: Magnesia
A42: =VLOOKUP(ListOfRegions!A25,ListOfRegions!A25:B99,2,0) -> Σποράδων | B42: 15 | C42: ― | D42: ― | E42: ― | F42: ― | G42: ― | H42: ― | I42: ― | J42: ― | K42: ― | L42: ― | M42: 15 | N42: 7.5 | O42: ― | P42: ― | Q42: ― | R42: ― | S42: ― | T42: ― | U42: ― | V42: ― | W42: Sporades Islands
A43: =VLOOKUP(ListOfRegions!A26,ListOfRegions!A26:B100,2,0) -> Τρικάλων | B43: 204046 | C43: 30465 | D43: 8208.119 | E43: 49466 | F43: 13114.675 | G43: 18078 | H43: 4814.333 | I43: 5053 | J43: 997.705 | K43: 156 | L43: 20.088 | M43: 100476 | N43: 118981.79 | O43: 46 | P43: 12.5 | Q43: ― | R43: ― | S43: ― | T43: ― | U43: 306 | V43: 60.74 | W43: Trikala
A44: Περιφέρεια Στερεάς Ελλάδας | B44: 1122019 | C44: 23782 | D44: 5628.885 | E44: 838235 | F44: 248089.92 | G44: 111454 | H44: 29410.428 | I44: 34599 | J44: 6858.02 | K44: 40 | L44: 12.2 | M44: 103718 | N44: 106778.73 | O44: 1390 | P44: 264.6 | Q44: 8700 | R44: 6580 | S44: 100 | T44: 18 | U44: 1 | V44: 0.1 | W44: Region of Central Greece
A46: =VLOOKUP(ListOfRegions!A27,ListOfRegions!A27:B101,2,0) -> Φθιώτιδας | B46: 589078 | C46: 12634 | D46: 3751.6 | E46: 457435 | F46: 136212.91 | G46: 43611 | H46: 13477.75 | I46: 8535 | J46: 1850.42 | K46: 40 | L46: 12.2 | M46: 57960 | N46: 64624.16 | O46: 63 | P46: 23.45 | Q46: 8700 | R46: 6580 | S46: 100 | T46: 18 | U46: ― | V46: ― | W46: Pthiotida
A47: =VLOOKUP(ListOfRegions!A28,ListOfRegions!A28:B102,2,0) -> Βοιωτίας | B47: 370738 | C47: 150 | D47: 45 | E47: 301163 | F47: 98548.9 | G47: 34860 | H47: 8436.2 | I47: 6255 | J47: 1534.75 | K47: ― | L47: ― | M47: 28310 | N47: 30019 | O47: ― | P47: ― | Q47: ― | R47: ― | S47: ― | T47: ― | U47: ― | V47: ― | W47: Viotia
...
