Workbook

Sheet ListOfRegions
A1: 01 | B1: Ροδόπης | H1: ΑΠΟΚΕΝΤΡΩΜΕΝΗ ΔΙΟΙΚΗΣΗ ΜΑΚΕΔΟΝΙΑΣ - ΘΡΑΚΗΣ
A2: 02 | B2: Δράμας
A3: 03 | B3: Έβρου | D3: ΠΕΡΙΦΕΡΕΙΑ ΑΝΑΤΟΛΙΚΗΣ ΜΑΚΕΔΟΝΙΑΣ
A4: 04 | B4: Θάσου | D4: ΚΑΙ ΘΡΑΚΗΣ
A5: 05 | B5: Καβάλας
A6: 06 | B6: Ξάνθης
A7: 07 | B7: Θεσσαλονίκης
A8: 08 | B8: Ημαθίας
A9: 09 | B9: Κιλκίς
A10: 10 | B10: Πέλλας
A11: 11 | B11: Πιερίας | D11: ΠΕΡΙΦΕΡΕΙΑ ΚΕΝΤΡΙΚΗΣ ΜΑΚΕΔΟΝΙΑΣ
A12: 12 | B12: Σερρών
A13: 13 | B13: Χαλκιδικής
A14: 14 | B14: Κοζάνης
A15: 15 | B15: Γρεβενών
A16: 16 | B16: Καστοριάς
A17: 17 | B17: Φλώρινας
A18: 18 | B18: Ιωαννίνων
A19: 19 | B19: Άρτας
A20: 20 | B20: Θεσπρωτίας | D20: ΠΕΡΙΦΕΡΕΙΑ ΗΠΕΙΡΟΥ
A21: 21 | B21: Πρέβεζας
A22: 22 | B22: Λάρισας | H22: ΑΠΟΚΕΝΤΡΩΜΕΝΗ ΔΙΟΙΚΗΣΗ ΘΕΣΣΑΛΙΑΣ - ΣΤΕΡΕΑΣ ΕΛΛΑΔΑΣ
A23: 23 | B23: Καρδίτσας
A24: 24 | B24: Μαγνησίας | D24: ΠΕΡΙΦΕΡΕΙΑ ΘΕΣΣΑΛΙΑΣ
A25: 25 | B25: Σποράδων
A26: 26 | B26: Τρικάλων
A27: 27 | B27: Φθιώτιδας
A28: 28 | B28: Βοιωτίας
A29: 29 | B29: Εύβοιας | D29: ΠΕΡΙΦΕΡΕΙΑ ΣΤΕΡΕΑΣ ΕΛΛΑΔΑΣ
A30: 30 | B30: Ευρυτανίας
A31: 31 | B31: Φωκίδας
A32: 32 | B32: Κέρκυρας | H32: ΑΠΟΚΕΝΤΡΩΜΕΝΗ ΔΙΟΙΚΗΣΗ ΠΕΛΟΠΟΝΝΗΣΟΥ, ΔΥΤΙΚΗΣ ΕΛΛΑΔΑΣ ΚΑΙ ΙΟΝΙΟΥ
A33: 33 | B33: Ζακύνθου
A34: 34 | B34: Ιθάκης | D34: ΠΕΡΙΦΕΡΕΙΑ ΙΟΝΙΩΝ ΝΗΣΩΝ
A35: 35 | B35: Κεφαλληνίας
A36: 36 | B36: Λευκάδας
A37: 37 | B37: Αχαϊας
A38: 38 | B38: Αιτωλ/νανίας | D38: ΠΕΡΙΦΕΡΕΙΑ ΔΥΤΙΚΗΣ ΕΛΛΑΔΑΣ
A39: 39 | B39: Ηλείας
A40: 40 | B40: Αρκαδίας
...

Sheet Πίνακας2(α)Συνολικός
A1: 2. Αροτραίες καλλιέργειες | O1: 2. Crops on arable land
A2: 2α. Σιτηρά για καρπό. Εκτάσεις και παραγωγή κατά περιφέρειες και περιφερειακές ενότητες. Έτος 2013 | O2: Table 2a. Cereals for grain. Areas and production, by geograpic region and regional unities, 2013
A3: Εκτάσεις σε στρέμματα, παραγωγή σε τόνους | W3: Areas in stremmas, production in tons
A4: Περιφέρειες και Περιφερειακές Ενότητες | B4: Σύνολο Εκτάσεων Total Area | C4: Σιτάρι Wheat | G4: Κριθάρι Barley | I4: Βρώμη Oats | K4: Σίκαλη Rye | M4: Αραβόσιτος - Maize | Q4: Ρύζι Rice | S4: Σόργο Sorghum | U4: Λοιπά(1) Other | W4: Regions and Regional Unities (NUTS 2)
C6: Μαλακό Soft | E6: Σκληρό Hard | M6: χωρίς συγκαλλιέργεια grown alone | O6: συγκαλλιεργούμενος με φασόλια και άλλα είδη grown with beans and other crops
C7: 1 | D7: 2 | E7: 1 | F7: 2 | G7: 1 | H7: 2 | I7: 1 | J7: 2 | K7: 1 | L7: 2 | M7: 1 | N7: 2 | O7: 1 | P7: 2 | Q7: 1 | R7: 2 | S7: 1 | T7: 2 | U7: 1 | V7: 2
A8: Σύνολο Ελλάδας | B8: =SUM(C8,E8,G8,I8,K8,M8,O8,Q8,S8,U8) -> 11031406 | C8: =SUM(C10,C18,C27,C32,C38,C45,C52,C59,C64,C71,C81,C88,C103) -> 1836690 | D8: =SUM(D10,D18,D27,D32,D38,D45,D52,D59,D64,D71,D81,D88,D103) -> 520652.13 | E8: =SUM(E10,E18,E27,E32,E38,E45,E52,E59,E64,E71,E81,E88,E103) -> 4758143 | F8: =SUM(F10,F18,F27,F32,F38,F45,F52,F59,F64,F71,F81,F88,F103) -> 1311208 | G8: =SUM(G10,G18,G27,G32,G38,G45,G52,G59,G64,G71,G81,G88,G103) -> 1370879 | H8: =SUM(H10,H18,H27,H32,H38,H45,H52,H59,H64,H71,H81,H88,H103) -> 381071.18 | I8: =SUM(I10,I18,I27,I32,I38,I45,I52,I59,I64,I71,I81,I88,I103) -> 449487 | J8: =SUM(J10,J18,J27,J32,J38,J45,J52,J59,J64,J71,J81,J88,J103) -> 92238.205 | ... V8: =SUM(V10,V18,V27,V32,V38,V45,V52,V59,V64,V71,V81,V88,V103) -> 11345.866 | W8: Greece Total
A10: Περιφέρεια Ανατολικής Μακεδονίας και Θράκης | B10: =SUM(C10,E10,G10,I10,K10,M10,O10,Q10,S10,U10) -> 1596364 | C10: =SUM(C12:C17) -> 379703 | D10: =SUM(D12:D17) -> 118677.22 | E10: =SUM(E12:E17) -> 531848 | F10: =SUM(F12:F17) -> 153259.74 | G10: =SUM(G12:G17) -> 122171 | H10: =SUM(H12:H17) -> 34238.015 | I10: =SUM(I12:I17) -> 7612 | J10: =SUM(J12:J17) -> 1543.09 | ... V10: =SUM(V12:V17) -> 991.17 | W10: Region of Eastern Macedonia and Thrace
A12: =VLOOKUP(ListOfRegions!$A$1,ListOfRegions!$A$1:B75,2,0) -> Ροδόπης | B12: =SUM(C12,E12,G12,I12,K12,M12,O12,Q12,S12,U12) -> 222442 | C12: 68318 | D12: 21797 | E12: 87259 | F12: 24740.725 | G12: 38832 | H12: 10860.115 | I12: 1455 | J12: 246.25 | K12: 2145 | L12: 318.3 | M12: 23723 | N12: 26725.7 | O12: — | P12: — | Q12: 0 | R12: 0 | S12: — | T12: — | U12: 710 | V12: 152.5 | W12: Rodopi
A13: =VLOOKUP(ListOfRegions!$A$2,ListOfRegions!$A$2:B76,2,0) -> Δράμας | B13: =SUM(C13,E13,G13,I13,K13,M13,O13,Q13,S13,U13) -> 326637 | C13: 60443 | D13: 15686.77 | E13: 99851 | F13: 28030.085 | G13: 33197 | H13: 8309.45 | I13: 4860 | J13: 933.8 | K13: 750 | L13: 109 | M13: 127431 | N13: 125657.7 | O13: — | P13: — | Q13: 0 | R13: 0 | S13: — | T13: — | U13: 105 | V13: 31.53 | W13: Drama
A14: =VLOOKUP(ListOfRegions!A3,ListOfRegions!A3:B77,2,0) -> Έβρου | B14: =SUM(C14,E14,G14,I14,K14,M14,O14,Q14,S14,U14) -> 562194 | C14: 163774 | D14: 55377.569 | E14: 309516 | F14: 91180.88 | G14: 34777 | H14: 10829.84 | I14: 827 | J14: 270.64 | K14: 4299 | L14: 1201.56 | M14: 44068 | N14: 50543.14 | O14: — | P14: — | Q14: 2500 | R14: 1750 | S14: — | T14: — | U14: 2433 | V14: 796.14 | W14: Evros
A15: =VLOOKUP(ListOfRegions!A4,ListOfRegions!A4:B78,2,0) -> Θάσου | B15: =SUM(C15,E15,G15,I15,K15,M15,O15,Q15,S15,U15) -> 22 | C15: — | D15: — | E15: — | F15: — | G15: — | H15: — | I15: — | J15: — | K15: — | L15: — | M15: 22 | N15: 17.75 | O15: — | P15: — | Q15: 0 | R15: 0 | S15: — | T15: — | U15: — | V15: — | W15: Thasos
A16: =VLOOKUP(ListOfRegions!A5,ListOfRegions!A5:B79,2,0) -> Καβάλας | B16: =SUM(C16,E16,G16,I16,K16,M16,O16,Q16,S16,U16) -> 245913 | C16: 24696 | D16: 6675.305 | E16: 10434 | F16: 2500.3 | G16: 5775 | H16: 1274.69 | I16: 470 | J16: 92.4 | K16: 340 | L16: 79.52 | M16: 182293 | N16: 187253.25 | O16: 5 | P16: 4 | Q16: 21765 | R16: 15175.75 | S16: 80 | T16: 11 | U16: 55 | V16: 11 | W16: Kavala
A17: =VLOOKUP(ListOfRegions!A6,ListOfRegions!A6:B80,2,0) -> Ξάνθης | B17: =SUM(C17,E17,G17,I17,K17,M17,O17,Q17,S17,U17) -> 239156 | C17: 62472 | D17: 19140.58 | E17: 24788 | F17: 6807.755 | G17: 9590 | H17: 2963.92 | I17: — | J17: — | K17: 1015 | L17: 132.7 | M17: 141291 | N17: 159105.11 | O17: — | P17: — | Q17: 0 | R17: 0 | S17: — | T17: — | U17: — | V17: — | W17: Xanthi
A18: Περιφέρεια Κεντρικής Μακεδονίας | B18: =SUM(C18,E18,G18,I18,K18,M18,O18,Q18,S18,U18) -> 3480646 | C18: =SUM(C20:C26) -> 670645 | D18: =SUM(D20:D26) -> 175353.46 | E18: =SUM(E20:E26) -> 1632197 | F18: =SUM(F20:F26) -> 390054.24 | G18: =SUM(G20:G26) -> 335651 | H18: =SUM(H20:H26) -> 106553.94 | I18: =SUM(I20:I26) -> 48585 | J18: =SUM(J20:J26) -> 9761.18 | ... V18: =SUM(V20:V26) -> 7787.972 | W18: Region of Central Macedonia
A20: =VLOOKUP(ListOfRegions!A7,ListOfRegions!A7:B81,2,0) -> Θεσσαλονίκης | B20: =SUM(C20,E20,G20,I20,K20,M20,O20,Q20,S20,U20) -> 867997 | C20: 201238 | D20: 55396.69 | E20: 271096 | F20: 72347.332 | G20: 117882 | H20: 35286.705 | I20: 17657 | J20: 3717.05 | K20: 16645 | L20: 3150.99 | M20: 57438 | N20: 67608.8 | O20: — | P20: — | Q20: 177582 | R20: 168093.2 | S20: — | T20: — | U20: 8459 | V20: 2262.11 | W20: Thessaloniki
A21: =VLOOKUP(ListOfRegions!A8,ListOfRegions!A8:B82,2,0) -> Ημαθίας | B21: =SUM(C21,E21,G21,I21,K21,M21,O21,Q21,S21,U21) -> 148485 | C21: 17097 | D21: 6267.41 | E21: 52561 | F21: 17524.94 | G21: 10614 | H21: 3648.9 | I21: 170 | J21: 58.5 | K21: — | L21: — | M21: 54218 | N21: 53241.25 | O21: 190 | P21: 152 | Q21: 12815 | R21: 8077.8 | S21: — | T21: — | U21: 820 | V21: 260.9 | W21: Imathia
A22: =VLOOKUP(ListOfRegions!A9,ListOfRegions!A9:B83,2,0) -> Κιλκίς | B22: =SUM(C22,E22,G22,I22,K22,M22,O22,Q22,S22,U22) -> 693402 | C22: 205289 | D22: 39849.925 | E22: 395479 | F22: 76346.27 | G22: 30344 | H22: 6080.48 | I22: 3710 | J22: 667.94 | K22: 4744 | L22: 720.985 | M22: 33660 | N22: 32423.345 | O22: — | P22: — | Q22: 0 | R22: 0 | S22: 465 | T22: 61 | U22: 19711 | V22: 3601.282 | W22: Kilkis
A23: =VLOOKUP(ListOfRegions!A10,ListOfRegions!A10:B84,2,0) -> Πέλλας | B23: =SUM(C23,E23,G23,I23,K23,M23,O23,Q23,S23,U23) -> 252921 | C23: 33490 | D23: 9323.57 | E23: 82266 | F23: 26832.26 | G23: 43136 | H23: 15234.78 | I23: 2800 | J23: 570.635 | K23: 1558 | L23: 309.475 | M23: 88000 | N23: 87803.1 | O23: 50 | P23: 30 | Q23: 631 | R23: 529.03 | S23: — | T23: — | U23: 990 | V23: 288.1 | W23: Pella
A24: =VLOOKUP(ListOfRegions!A11,ListOfRegions!A11:B85,2,0) -> Πιερίας | B24: =SUM(C24,E24,G24,I24,K24,M24,O24,Q24,S24,U24) -> 243060 | C24: 59985 | D24: 19916.54 | E24: 116641 | F24: 33346.149 | G24: 21655 | H24: 7148.2 | I24: 4950 | J24: 1297.44 | K24: 90 | L24: 20.8 | M24: 28159 | N24: 32036.3 | O24: — | P24: — | Q24: 10580 | R24: 8464 | S24: — | T24: — | U24: 1000 | V24: 200 | W24: Pieria
A25: =VLOOKUP(ListOfRegions!A12,ListOfRegions!A12:B86,2,0) -> Σερρών | B25: =SUM(C25,E25,G25,I25,K25,M25,O25,Q25,S25,U25) -> 903051 | C25: 110910 | D25: 36188.225 | E25: 447496 | F25: 109515.59 | G25: 75654 | H25: 29186.525 | I25: 930 | J25: 262.6 | K25: 3580 | L25: 929.14 | M25: 231449 | N25: 259470.32 | O25: — | P25: — | Q25: 30736 | R25: 17971.98 | S25: — | T25: — | U25: 2296 | V25: 610.23 | W25: Serres
A26: =VLOOKUP(ListOfRegions!A13,ListOfRegions!A13:B87,2,0) -> Χαλκιδικής | B26: =SUM(C26,E26,G26,I26,K26,M26,O26,Q26,S26,U26) -> 371730 | C26: 42636 | D26: 8411.095 | E26: 266658 | F26: 54141.695 | G26: 36366 | H26: 9968.35 | I26: 18368 | J26: 3187.015 | K26: 951 | L26: 166.68 | M26: 2972 | N26: 3168.43 | O26: 10 | P26: 2 | Q26: 0 | R26: 0 | S26: — | T26: — | U26: 3769 | V26: 565.35 | W26: Chalkidiki | AB26: —
A27: Περιφέρεια Δυτικής Μακεδονίας | B27: =SUM(C27,E27,G27,I27,K27,M27,O27,Q27,S27,U27) -> 1361286 | C27: =SUM(C28:C31) -> 481295 | D27: =SUM(D28:D31) -> 136818.49 | E27: =SUM(E28:E31) -> 403312 | F27: =SUM(F28:F31) -> 100348.37 | G27: =SUM(G28:G31) -> 216860 | H27: =SUM(H28:H31) -> 64497.04 | I27: =SUM(I28:I31) -> 10650 | J27: =SUM(J28:J31) -> 2469.325 | ... V27: =SUM(V28:V31) -> 1769.64 | W27: Region of Western Macedonia
A28: =VLOOKUP(ListOfRegions!A14,ListOfRegions!A14:B88,2,0) -> Κοζάνης | B28: =SUM(C28,E28,G28,I28,K28,M28,O28,Q28,S28,U28) -> 676839 | C28: 182922 | D28: 56447.452 | E28: 328536 | F28: 83658.268 | G28: 80672 | H28: 27138.176 | I28: 6464 | J28: 1479.2 | K28: 15147 | L28: 3523.25 | M28: 62033 | N28: 79985.68 | O28: 45 | P28: 33.1 | Q28: 0 | R28: 0 | S28: — | T28: — | U28: 1020 | V28: 195.1 | W28: Kozani
A29: =VLOOKUP(ListOfRegions!A15,ListOfRegions!A15:B89,2,0) -> Γρεβενών | B29: =SUM(C29,E29,G29,I29,K29,M29,O29,Q29,S29,U29) -> 255705 | C29: 171312 | D29: 51226.885 | E29: 8773 | F29: 2400.97 | G29: 58260 | H29: 18936.24 | I29: 3378 | J29: 817.625 | K29: 798 | L29: 127.6 | M29: 7626 | N29: 8078.25 | O29: — | P29: — | Q29: 0 | R29: 0 | S29: — | T29: — | U29: 5558 | V29: 1268.14 | W29: Grevena
A30: =VLOOKUP(ListOfRegions!A16,ListOfRegions!A16:B90,2,0) -> Καστοριάς | B30: =SUM(C30,E30,G30,I30,K30,M30,O30,Q30,S30,U30) -> 159361 | C30: 78500 | D30: 16807.83 | E30: 39387 | F30: 7977.88 | G30: 15077 | H30: 3553.32 | I30: 658 | J30: 139.5 | K30: 12429 | L30: 2512.18 | M30: 12801 | N30: 12691.3 | O30: 9 | P30: 0.9 | Q30: 0 | R30: 0 | S30: — | T30: — | U30: 500 | V30: 100 | W30: Kastoria
A31: =VLOOKUP(ListOfRegions!A17,ListOfRegions!A17:B91,2,0) -> Φλώρινας | B31: =SUM(C31,E31,G31,I31,K31,M31,O31,Q31,S31,U31) -> 269381 | C31: 48561 | D31: 12336.325 | E31: 26616 | F31: 6311.25 | G31: 62851 | H31: 14869.304 | I31: 150 | J31: 33 | K31: 68265 | L31: 14926.889 | M31: 61901 | N31: 75344.91 | O31: — | P31: — | Q31: 0 | R31: 0 | S31: — | T31: — | U31: 1037 | V31: 206.4 | W31: Florina
A32: Περιφέρεια Ηπείρου | B32: =SUM(C32,E32,G32,I32,K32,M32,O32,Q32,S32,U32) -> 154455 | C32: =SUM(C34:C37) -> 4806 | D32: =SUM(D34:D37) -> 1277.35 | E32: =SUM(E34:E37) -> 1440 | F32: =SUM(F34:F37) -> 363.28 | G32: =SUM(G34:G37) -> 7199 | H32: =SUM(H34:H37) -> 1762.48 | I32: =SUM(I34:I37) -> 15225 | J32: =SUM(J34:J37) -> 3915.086 | ... V32: =SUM(V34:V37) -> 7.16 | W32: Region of Epirus
A34: =VLOOKUP(ListOfRegions!A18,ListOfRegions!A18:B92,2,0) -> Ιωαννίνων | B34: =SUM(C34,E34,G34,I34,K34,M34,O34,Q34,S34,U34) -> 55744 | C34: 3736 | D34: 1077.81 | E34: 420 | F34: 84.73 | G34: 4443 | H34: 1035.65 | I34: 1696 | J34: 341.456 | K34: 8487 | L34: 1774.96 | M34: 36236 | N34: 33352.675 | O34: 669 | P34: 255.4 | Q34: 0 | R34: 0 | S34: 50 | T34: 7 | U34: 7 | V34: 2.36 | W34: Ionnina
A35: =VLOOKUP(ListOfRegions!A19,ListOfRegions!A19:B93,2,0) -> Άρτας | B35: =SUM(C35,E35,G35,I35,K35,M35,O35,Q35,S35,U35) -> 27015 | C35: 990 | D35: 186.4 | E35: 655 | F35: 195.4 | G35: 1368 | H35: 415.38 | I35: 3709 | J35: 974.35 | K35: 23 | L35: 3.6 | M35: 18772 | N35: 15876.5 | O35: 798 | P35: 327.7 | Q35: 670 | R35: 335 | S35: — | T35: — | U35: 30 | V35: 4.8 | W35: Arta
A36: =VLOOKUP(ListOfRegions!A20,ListOfRegions!A20:B94,2,0) -> Θεσπρωτίας | B36: =SUM(C36,E36,G36,I36,K36,M36,O36,Q36,S36,U36) -> 20492 | C36: 3 | D36: 0.84 | E36: 10 | F36: 2 | G36: 623 | H36: 160 | I36: 3148 | J36: 712.6 | K36: 101 | L36: 12.9 | M36: 14503 | N36: 14245.96 | O36: 4 | P36: 0.75 | Q36: 2100 | R36: 1660 | S36: — | T36: — | U36: — | V36: — | W36: Thesprotia
A37: =VLOOKUP(ListOfRegions!A21,ListOfRegions!A21:B95,2,0) -> Πρέβεζας | B37: =SUM(C37,E37,G37,I37,K37,M37,O37,Q37,S37,U37) -> 51204 | C37: 77 | D37: 12.3 | E37: 355 | F37: 81.15 | G37: 765 | H37: 151.45 | I37: 6672 | J37: 1886.68 | K37: 346 | L37: 68.7 | M37: 42914 | N37: 44758.633 | O37: 5 | P37: 8 | Q37: 0 | R37: 0 | S37: 70 | T37: 8 | U37: — | V37: — | W37: Preveza
A38: Περιφέρεια Θεσσαλίας | B38: =SUM(C38,E38,G38,I38,K38,M38,O38,Q38,S38,U38) -> 2094709 | C38: =SUM(C40:C44) -> 211287 | D38: =SUM(D40:D44) -> 66393.278 | E38: =SUM(E40:E44) -> 1170883 | F38: =SUM(F40:F44) -> 395482.18 | G38: =SUM(G40:G44) -> 305267 | H38: =SUM(H40:H44) -> 99091.847 | I38: =SUM(I40:I44) -> 40185 | J38: =SUM(J40:J44) -> 10714.042 | ... V38: =SUM(V40:V44) -> 734.5 | W38: Region of Thessally
A40: =VLOOKUP(ListOfRegions!A22,ListOfRegions!A22:B96,2,0) -> Λάρισας | B40: =SUM(C40,E40,G40,I40,K40,M40,O40,Q40,S40,U40) -> 1313769 | C40: 141385 | D40: 43103.506 | E40: 786815 | F40: 274395.09 | G40: 199818 | H40: 67101.48 | I40: 23790 | J40: 6732.712 | K40: 6412 | L40: 1380.12 | M40: 151031 | N40: 185940.85 | O40: 1500 | P40: 1710 | Q40: — | R40: — | S40: 100 | T40: 100 | U40: 2918 | V40: 701.5 | W40: Larissa
A41: =VLOOKUP(ListOfRegions!A23,ListOfRegions!A23:B97,2,0) -> Καρδίτσας | B41: =SUM(C41,E41,G41,I41,K41,M41,O41,Q41,S41,U41) -> 308276 | C41: 23782 | D41: 8354.5 | E41: 192388 | F41: 67690.85 | G41: 10696 | H41: 3566.1 | I41: 7545 | J41: 2039 | K41: 30 | L41: 4.5 | M41: 73694 | N41: 79135.475 | O41: 141 | P41: 31.85 | Q41: — | R41: — | S41: — | T41: — | U41: — | V41: — | W41: Karditsa
A42: =VLOOKUP(ListOfRegions!A24,ListOfRegions!A24:B98,2,0) -> Μαγνησίας | B42: =SUM(C42,E42,G42,I42,K42,M42,O42,Q42,S42,U42) -> 264037 | C42: 10350 | D42: 2746 | E42: 148952 | F42: 38063.6 | G42: 73211 | H42: 21283.85 | I42: 4006 | J42: 773.5 | K42: — | L42: — | M42: 27518 | N42: 38193.8 | P42: 0 | Q42: — | R42: — | S42: — | T42: — | U42: — | V42: — | W42: Magnesia
A43: =VLOOKUP(ListOfRegions!A25,ListOfRegions!A25:B99,2,0) -> Σποράδων | B43: =SUM(C43,E43,G43,I43,K43,M43,O43,Q43,S43,U43) -> 15 | C43: — | D43: — | E43: — | F43: — | G43: — | H43: — | I43: — | J43: — | K43: — | L43: — | M43: 15 | N43: 8 | O43: — | P43: — | Q43: — | R43: — | S43: — | T43: — | U43: — | V43: — | W43: Sporades Islands
A44: =VLOOKUP(ListOfRegions!A26,ListOfRegions!A26:B100,2,0) -> Τρικάλων | B44: =SUM(C44,E44,G44,I44,K44,M44,O44,Q44,S44,U44) -> 208612 | C44: 35770 | D44: 12189.272 | E44: 42728 | F44: 15332.635 | G44: 21542 | H44: 7140.417 | I44: 4844 | J44: 1168.83 | K44: 222 | L44: 28.52 | M44: 103310 | N44: 126294.98 | O44: 34 | P44: 9.6 | Q44: — | R44: — | S44: — | T44: — | U44: 162 | V44: 33 | W44: Trikala
A45: Περιφέρεια Στερεάς Ελλάδας | B45: =SUM(C45,E45,G45,I45,K45,M45,O45,Q45,S45,U45) -> 1072570 | C45: =SUM(C47:C51) -> 32771 | D45: =SUM(D47:D51) -> 8553.365 | E45: =SUM(E47:E51) -> 780579 | F45: =SUM(F47:F51) -> 227924.93 | G45: =SUM(G47:G51) -> 113263 | H45: =SUM(H47:H51) -> 29442.48 | I45: =SUM(I47:I51) -> 34428 | J45: =SUM(J47:J51) -> 6624.36 | ... V45: =SUM(V47:V51) -> 0 | W45: Region of Central Greece
A47: =VLOOKUP(ListOfRegions!A27,ListOfRegions!A27:B101,2,0) -> Φθιώτιδας | B47: =SUM(C47,E47,G47,I47,K47,M47,O47,Q47,S47,U47) -> 574893 | C47: 19887 | D47: 5541.275 | E47: 435888 | F47: 122960.97 | G47: 43020 | H47: 12827.1 | I47: 9424 | J47: 1938 | K47: 31 | L47: 9.6 | M47: 57781 | N47: 60503.17 | O47: 62 | P47: 26.63 | Q47: 8700 | R47: 6578.76 | S47: 100 | T47: 16 | U47: — | V47: — | W47: Pthiotida
...

Sheet Sheet1
