Workbook

Sheet Φύλλο1
C1: Ενημέρωση, Δεκέμβριος 2024
A2: ΕΛΛΗΝΙΚΗ ΣΤΑΤΙΣΤΙΚΗ ΑΡΧΗ
A3: Οικονομικοί Λογαριασμοί Γεωργίας κατά γεωγραφική ζώνη και περιφέρεια
A4: Ετος 2023
A5: Σε εκατομμύρια ευρώ.
A6: ΚΑΤΗΓΟΡΙΕΣ | B6: ΠΕΡΙΓΡΑΦΗ | C6: Σύνολο Ελλάδος | D6: Αττική | E6: Νησιά Αιγαίου, Κρήτη | F6: Βόρειο Αιγαίο | G6: Νότιο Αιγαίο | H6: Κρήτη | I6: Βόρεια Ελλάδα | J6: Aνατολική Μακεδονία, Θράκη | K6: Κεντρική Μακεδονία | L6: Δυτική Μακεδονία | M6: Ήπειρος | N6: Κεντρική Ελλάδα | O6: Θεσσαλία | P6: Ιόνια Νησιά | Q6: Δυτική Ελλάδα | R6: Στερεά Ελλάδα | S6: Πελοπόννησος
A7: 01 | B7: ΔΗΜΗΤΡΙΑKΑ (περιλαμβανομένων των σπόρων) | C7: =[1]Φύλλο!E4 -> 1052.93 | D7: =[1]Φύλλο!F4 -> 2.0329404 | E7: =[1]Φύλλο!H4 -> 6.4649412 | F7: =[1]Φύλλο!I4 -> 3.4456225 | G7: =[1]Φύλλο!J4 -> 2.166329 | H7: =[1]Φύλλο!K4 -> 0.85298961 | I7: =[1]Φύλλο!L4 -> 664.43861 | J7: =[1]Φύλλο!M4 -> 215.10265 | K7: =[1]Φύλλο!N4 -> 360.17137 | L7: =[1]Φύλλο!O4 -> 75.717719 | ... S7: =[1]Φύλλο!V4 -> 11.042566
A8: 01.1 | B8: Σιτάρι και όλυρα | C8: =[1]Φύλλο!E5 -> 444.71 | D8: =[1]Φύλλο!F5 -> 1.4107746 | E8: =[1]Φύλλο!H5 -> 2.0879139 | F8: =[1]Φύλλο!I5 -> 0.45690048 | G8: =[1]Φύλλο!J5 -> 1.5661541 | H8: =[1]Φύλλο!K5 -> 0.064859299 | I8: =[1]Φύλλο!L5 -> 266.58964 | J8: =[1]Φύλλο!M5 -> 83.497837 | K8: =[1]Φύλλο!N5 -> 145.35884 | L8: =[1]Φύλλο!O5 -> 37.022087 | ... S8: =[1]Φύλλο!V5 -> 4.5383356
A9: 01.11 | B9: Μαλακό σιτάρι και όλυρα | C9: =[1]Φύλλο!E6 -> 91.07 | D9: =[1]Φύλλο!F6 -> 0.041025434 | E9: =[1]Φύλλο!H6 -> 0.59971461 | F9: =[1]Φύλλο!I6 -> 0.18935289 | G9: =[1]Φύλλο!J6 -> 0.3747081 | H9: =[1]Φύλλο!K6 -> 0.035653622 | I9: =[1]Φύλλο!L6 -> 75.62667 | J9: =[1]Φύλλο!M6 -> 21.398139 | K9: =[1]Φύλλο!N6 -> 40.109598 | L9: =[1]Φύλλο!O6 -> 13.504306 | ... S9: =[1]Φύλλο!V6 -> 2.5953938
A10: 01.12 | B10: Σκληρό σιτάρι | C10: =[1]Φύλλο!E7 -> 353.64 | D10: =[1]Φύλλο!F7 -> 1.3697492 | E10: =[1]Φύλλο!H7 -> 1.4881993 | F10: =[1]Φύλλο!I7 -> 0.26754759 | G10: =[1]Φύλλο!J7 -> 1.191446 | H10: =[1]Φύλλο!K7 -> 0.029205677 | I10: =[1]Φύλλο!L7 -> 190.96297 | J10: =[1]Φύλλο!M7 -> 62.099698 | K10: =[1]Φύλλο!N7 -> 105.24925 | L10: =[1]Φύλλο!O7 -> 23.517781 | ... S10: =[1]Φύλλο!V7 -> 1.9429418
A11: 01.2 | B11: Σίκαλη και σμιγός | C11: =[1]Φύλλο!E8 -> 3.31 | D11: =[1]Φύλλο!F8 -> 0.0042384281 | E11: =[1]Φύλλο!H8 -> 0.21092128 | F11: =[1]Φύλλο!I8 -> 0.009123869 | G11: =[1]Φύλλο!J8 -> 0.019470673 | H11: =[1]Φύλλο!K8 -> 0.18232674 | I11: =[1]Φύλλο!L8 -> 2.7310592 | J11: =[1]Φύλλο!M8 -> 0.1285392 | K11: =[1]Φύλλο!N8 -> 0.38963483 | L11: =[1]Φύλλο!O8 -> 2.1274884 | ... S11: =[1]Φύλλο!V8 -> 0.057423952
A12: 01.3 | B12: Κριθάρι | C12: =[1]Φύλλο!E9 -> 78.31 | D12: =[1]Φύλλο!F9 -> 0.32075828 | E12: =[1]Φύλλο!H9 -> 3.6982421 | F12: =[1]Φύλλο!I9 -> 2.7915912 | G12: =[1]Φύλλο!J9 -> 0.47542683 | H12: =[1]Φύλλο!K9 -> 0.43122407 | I12: =[1]Φύλλο!L9 -> 38.083318 | J12: =[1]Φύλλο!M9 -> 6.8413356 | K12: =[1]Φύλλο!N9 -> 23.895686 | L12: =[1]Φύλλο!O9 -> 7.2205939 | ... S12: =[1]Φύλλο!V9 -> 1.9463369
A13: 01.4 | B13: Βρώμη και μείγματα θερινών δημητριακών | C13: =[1]Φύλλο!E10 -> 22.59 | D13: =[1]Φύλλο!F10 -> 0.21062507 | E13: =[1]Φύλλο!H10 -> 0.397125 | F13: =[1]Φύλλο!I10 -> 0.1661412 | G13: =[1]Φύλλο!J10 -> 0.097557862 | H13: =[1]Φύλλο!K10 -> 0.13342594 | I13: =[1]Φύλλο!L10 -> 3.5664549 | J13: =[1]Φύλλο!M10 -> 0.75807766 | K13: =[1]Φύλλο!N10 -> 1.8730392 | L13: =[1]Φύλλο!O10 -> 0.37037794 | ... S13: =[1]Φύλλο!V10 -> 3.2850936
A14: 01.5 | B14: Αραβόσιτος σε κόκκους | C14: =[1]Φύλλο!E11 -> 434.88 | D14: =[1]Φύλλο!F11 -> 0.086544021 | E14: =[1]Φύλλο!H11 -> 0.070738883 | F14: =[1]Φύλλο!I11 -> 0.021865754 | G14: =[1]Φύλλο!J11 -> 0.0077195619 | H14: =[1]Φύλλο!K11 -> 0.041153567 | I14: =[1]Φύλλο!L11 -> 288.87734 | J14: =[1]Φύλλο!M11 -> 118.48893 | K14: =[1]Φύλλο!N11 -> 129.48077 | L14: =[1]Φύλλο!O11 -> 28.977172 | ... S14: =[1]Φύλλο!V11 -> 1.1441123
A15: 01.6 | B15: Ρύζι | C15: =[1]Φύλλο!E12 -> 69.13 | D15: =[1]Φύλλο!F12 -> 0 | E15: =[1]Φύλλο!H12 -> 0 | F15: =[1]Φύλλο!I12 -> 0 | G15: =[1]Φύλλο!J12 -> 0 | H15: =[1]Φύλλο!K12 -> 0 | I15: =[1]Φύλλο!L12 -> 64.590786 | J15: =[1]Φύλλο!M12 -> 5.38793 | K15: =[1]Φύλλο!N12 -> 59.173393 | L15: =[1]Φύλλο!O12 -> 0 | ... S15: =[1]Φύλλο!V12 -> 0.071264073
A16: 01.9 | B16: Αλλα δημητριακά | C16: =[1]Φύλλο!E13 -> 0 | D16: =[1]Φύλλο!F13 -> 0 | E16: =[1]Φύλλο!H13 -> 0 | F16: =[1]Φύλλο!I13 -> 0 | G16: =[1]Φύλλο!J13 -> 0 | H16: =[1]Φύλλο!K13 -> 0 | I16: =[1]Φύλλο!L13 -> 0 | J16: =[1]Φύλλο!M13 -> 0 | K16: =[1]Φύλλο!N13 -> 0 | L16: =[1]Φύλλο!O13 -> 0 | ... S16: =[1]Φύλλο!V13 -> 0
A17: 02 | B17: ΒΙΟΜΗΧΑΝΙΚΑ ΦΥΤΑ | C17: =[1]Φύλλο!E14 -> 915.02 | D17: =[1]Φύλλο!F14 -> 1.2247831 | E17: =[1]Φύλλο!H14 -> 3.042696 | F17: =[1]Φύλλο!I14 -> 2.6116884 | G17: =[1]Φύλλο!J14 -> 0.3129563 | H17: =[1]Φύλλο!K14 -> 0.11805131 | I17: =[1]Φύλλο!L14 -> 505.77063 | J17: =[1]Φύλλο!M14 -> 205.04606 | K17: =[1]Φύλλο!N14 -> 267.44897 | L17: =[1]Φύλλο!O14 -> 32.525758 | ... S17: =[1]Φύλλο!V14 -> 1.46725
A18: 02.1 | B18: Ελαιούχοι σπόροι και καρποί (περιλαμβανομένων των σπόρων) | C18: =[1]Φύλλο!E15 -> 100.81 | D18: =[1]Φύλλο!F15 -> 0 | E18: =[1]Φύλλο!H15 -> 0.037501912 | F18: =[1]Φύλλο!I15 -> 0.034337561 | G18: =[1]Φύλλο!J15 -> 0.0027555419 | H18: =[1]Φύλλο!K15 -> 0.00040880901 | I18: =[1]Φύλλο!L15 -> 97.105319 | J18: =[1]Φύλλο!M15 -> 62.59797 | K18: =[1]Φύλλο!N15 -> 26.138193 | L18: =[1]Φύλλο!O15 -> 8.319254 | ... S18: =[1]Φύλλο!V15 -> 0.21196227
... A27: 03 | B27: ΚΤΗΝΟΤΡΟΦΙΚΑ ΦΥΤΑ | C27: =[1]Φύλλο!E24 -> 918.99952 | D27: =[1]Φύλλο!F24 -> 3.0646585 | E27: =[1]Φύλλο!H24 -> 150.08377 | F27: =[1]Φύλλο!I24 -> 27.110333 | G27: =[1]Φύλλο!J24 -> 38.313292 | H27: =[1]Φύλλο!K24 -> 84.660143 | I27: =[1]Φύλλο!L24 -> 214.64516 | J27: =[1]Φύλλο!M24 -> 37.564088 | K27: =[1]Φύλλο!N24 -> 104.95568 | L27: =[1]Φύλλο!O24 -> 59.19606 | ... S27: =[1]Φύλλο!V24 -> 69.510658
A28: 04 | B28: ΛΑΧΑΝΙΚΑ ΚΑΙ ΣΚΑΛΙΣΤΙΚΑ ΦΥΤΑ | C28: =[1]Φύλλο!E28 -> 2007.5808 | D28: =[1]Φύλλο!F28 -> 70.592564 | E28: =[1]Φύλλο!H28 -> 521.93331 | F28: =[1]Φύλλο!I28 -> 8.4950435 | G28: =[1]Φύλλο!J28 -> 9.2333084 | H28: =[1]Φύλλο!K28 -> 504.20495 | I28: =[1]Φύλλο!L28 -> 307.18189 | J28: =[1]Φύλλο!M28 -> 33.651367 | K28: =[1]Φύλλο!N28 -> 224.90981 | L28: =[1]Φύλλο!O28 -> 10.801421 | ... S28: =[1]Φύλλο!V28 -> 168.2269
A29: 04.1 | B29: Νωπά λαχανικά | C29: =[1]Φύλλο!E29 -> 1837.5878 | D29: =[1]Φύλλο!F29 -> 24.686414 | E29: =[1]Φύλλο!H29 -> 505.79607 | F29: =[1]Φύλλο!I29 -> 7.7241006 | G29: =[1]Φύλλο!J29 -> 7.7439867 | H29: =[1]Φύλλο!K29 -> 490.32798 | I29: =[1]Φύλλο!L29 -> 245.06841 | J29: =[1]Φύλλο!M29 -> 30.164603 | K29: =[1]Φύλλο!N29 -> 169.76987 | L29: =[1]Φύλλο!O29 -> 10.240735 | ... S29: =[1]Φύλλο!V29 -> 163.26834
A30: 04.2 | B30: Φυτά και λουλούδια | C30: =[1]Φύλλο!E30 -> 169.99292 | D30: =[1]Φύλλο!F30 -> 45.906149 | E30: =[1]Φύλλο!H30 -> 16.137238 | F30: =[1]Φύλλο!I30 -> 0.77094297 | G30: =[1]Φύλλο!J30 -> 1.4893216 | H30: =[1]Φύλλο!K30 -> 13.876973 | I30: =[1]Φύλλο!L30 -> 62.113473 | J30: =[1]Φύλλο!M30 -> 3.4867648 | K30: =[1]Φύλλο!N30 -> 55.139944 | L30: =[1]Φύλλο!O30 -> 0.56068579 | ... S30: =[1]Φύλλο!V30 -> 4.958565
A31: 05 | B31: ΠΑΤΑΤΕΣ (περιλαμβανομένων των σπόρων) | C31: =[1]Φύλλο!E31 -> 217.73 | D31: =[1]Φύλλο!F31 -> 1.7021584 | E31: =[1]Φύλλο!H31 -> 21.569673 | F31: =[1]Φύλλο!I31 -> 2.5296391 | G31: =[1]Φύλλο!J31 -> 12.383478 | H31: =[1]Φύλλο!K31 -> 6.6565556 | I31: =[1]Φύλλο!L31 -> 99.781015 | J31: =[1]Φύλλο!M31 -> 54.052741 | K31: =[1]Φύλλο!N31 -> 17.240116 | L31: =[1]Φύλλο!O31 -> 26.256346 | ... S31: =[1]Φύλλο!V31 -> 15.479327
A32: 06 | B32: ΦΡΟΥΤΑ | C32: =[1]Φύλλο!E32 -> 4368.4822 | D32: =[1]Φύλλο!F32 -> 25.954116 | E32: =[1]Φύλλο!H32 -> 226.88393 | F32: =[1]Φύλλο!I32 -> 23.133011 | G32: =[1]Φύλλο!J32 -> 27.38675 | H32: =[1]Φύλλο!K32 -> 176.36417 | I32: =[1]Φύλλο!L32 -> 2464.933 | J32: =[1]Φύλλο!M32 -> 164.13638 | K32: =[1]Φύλλο!N32 -> 1818.321 | L32: =[1]Φύλλο!O32 -> 363.90377 | ... S32: =[1]Φύλλο!V32 -> 650.78305
A33: 06.1 | B33: Νωπά φρούτα | C33: =[1]Φύλλο!E33 -> 2895.2822 | D33: =[1]Φύλλο!F33 -> 1.8765514 | E33: =[1]Φύλλο!H33 -> 30.69977 | F33: =[1]Φύλλο!I33 -> 2.4472927 | G33: =[1]Φύλλο!J33 -> 5.9590474 | H33: =[1]Φύλλο!K33 -> 22.293429 | I33: =[1]Φύλλο!L33 -> 2104.684 | J33: =[1]Φύλλο!M33 -> 58.14695 | K33: =[1]Φύλλο!N33 -> 1690.5467 | L33: =[1]Φύλλο!O33 -> 351.32963 | ... S33: =[1]Φύλλο!V33 -> 206.47243
A34: 06.2 | B34: Εσπεριδοειδή | C34: =[1]Φύλλο!E34 -> 481.64 | D34: =[1]Φύλλο!F34 -> 1.8101116 | E34: =[1]Φύλλο!H34 -> 30.242593 | F34: =[1]Φύλλο!I34 -> 1.4491848 | G34: =[1]Φύλλο!J34 -> 4.5078624 | H34: =[1]Φύλλο!K34 -> 24.285545 | I34: =[1]Φύλλο!L34 -> 67.527196 | J34: =[1]Φύλλο!M34 -> 0.0066535691 | K34: =[1]Φύλλο!N34 -> 0.017655194 | L34: =[1]Φύλλο!O34 -> 0 | ... S34: =[1]Φύλλο!V34 -> 272.91682
A35: 06.3 | B35: Τροπικά φρούτα | C35: =[1]Φύλλο!E35 -> 126.24 | D35: =[1]Φύλλο!F35 -> 0.32245386 | E35: =[1]Φύλλο!H35 -> 0.98583327 | F35: =[1]Φύλλο!I35 -> 0.24058036 | G35: =[1]Φύλλο!J35 -> 0.11448292 | H35: =[1]Φύλλο!K35 -> 0.63077 | I35: =[1]Φύλλο!L35 -> 105.62262 | J35: =[1]Φύλλο!M35 -> 23.096808 | K35: =[1]Φύλλο!N35 -> 49.960491 | L35: =[1]Φύλλο!O35 -> 0.093811985 | ... S35: =[1]Φύλλο!V35 -> 3.3434994
A36: 06.4 | B36: Σταφύλια | C36: =[1]Φύλλο!E36 -> 485.38 | D36: =[1]Φύλλο!F36 -> 15.850069 | E36: =[1]Φύλλο!H36 -> 89.190894 | F36: =[1]Φύλλο!I36 -> 14.353913 | G36: =[1]Φύλλο!J36 -> 8.8465906 | H36: =[1]Φύλλο!K36 -> 65.99039 | I36: =[1]Φύλλο!L36 -> 142.56915 | J36: =[1]Φύλλο!M36 -> 65.440893 | K36: =[1]Φύλλο!N36 -> 62.343411 | L36: =[1]Φύλλο!O36 -> 12.333053 | ... S36: =[1]Φύλλο!V36 -> 63.689932
A37: 06.5 | B37: Ελιές | C37: =[1]Φύλλο!E37 -> 379.94 | D37: =[1]Φύλλο!F37 -> 6.0949297 | E37: =[1]Φύλλο!H37 -> 75.764841 | F37: =[1]Φύλλο!I37 -> 4.6420403 | G37: =[1]Φύλλο!J37 -> 7.9587672 | H37: =[1]Φύλλο!K37 -> 63.164033 | I37: =[1]Φύλλο!L37 -> 44.530093 | J37: =[1]Φύλλο!M37 -> 17.445073 | K37: =[1]Φύλλο!N37 -> 15.452788 | L37: =[1]Φύλλο!O37 -> 0.14727817 | ... S37: =[1]Φύλλο!V37 -> 104.36036
A38: 07 | B38: ΚΡΑΣΙ | C38: =[1]Φύλλο!E38 -> 92.900372 | D38: =[1]Φύλλο!F38 -> 2.5699961 | E38: =[1]Φύλλο!H38 -> 16.548674 | F38: =[1]Φύλλο!I38 -> 1.5642303 | G38: =[1]Φύλλο!J38 -> 1.8955784 | H38: =[1]Φύλλο!K38 -> 13.088865 | I38: =[1]Φύλλο!L38 -> 14.917151 | J38: =[1]Φύλλο!M38 -> 2.9521686 | K38: =[1]Φύλλο!N38 -> 9.7766614 | L38: =[1]Φύλλο!O38 -> 1.5569359 | ... S38: =[1]Φύλλο!V38 -> 12.852359
A39: 08 | B39: ΕΛΑΙΟΛΑΔΟ | C39: =[1]Φύλλο!E39 -> 1592.56 | D39: =[1]Φύλλο!F39 -> 37.354857 | E39: =[1]Φύλλο!H39 -> 540.11871 | F39: =[1]Φύλλο!I39 -> 47.27942 | G39: =[1]Φύλλο!J39 -> 6.805638 | H39: =[1]Φύλλο!K39 -> 486.03365 | I39: =[1]Φύλλο!L39 -> 74.192277 | J39: =[1]Φύλλο!M39 -> 44.681854 | K39: =[1]Φύλλο!N39 -> 12.692346 | L39: =[1]Φύλλο!O39 -> 0.66188743 | ... S39: =[1]Φύλλο!V39 -> 603.26071
A40: 09 | B40: ΑΛΛΑ ΦΥΤΙΚΑ ΠΡΟΪΟΝΤΑ | C40: =[1]Φύλλο!E40 -> 138.30691 | D40: =[1]Φύλλο!F40 -> 22.046343 | E40: =[1]Φύλλο!H40 -> 9.3893164 | F40: =[1]Φύλλο!I40 -> 0.39241064 | G40: =[1]Φύλλο!J40 -> 0.94178553 | H40: =[1]Φύλλο!K40 -> 8.0551202 | I40: =[1]Φύλλο!L40 -> 59.824785 | J40: =[1]Φύλλο!M40 -> 5.764869 | K40: =[1]Φύλλο!N40 -> 49.693456 | L40: =[1]Φύλλο!O40 -> 1.0202677 | ... S40: =[1]Φύλλο!V40 -> 14.034031
A41: 10 | B41: ΦΥΤΙΚΗ ΠΑΡΑΓΩΓΗ (1 ΕΩΣ 9) | C41: =[1]Φύλλο!E41 -> 11304.51 | D41: =[1]Φύλλο!F41 -> 166.54242 | E41: =[1]Φύλλο!H41 -> 1496.035 | F41: =[1]Φύλλο!I41 -> 116.5614 | G41: =[1]Φύλλο!J41 -> 99.439117 | H41: =[1]Φύλλο!K41 -> 1280.0345 | I41: =[1]Φύλλο!L41 -> 4405.6846 | J41: =[1]Φύλλο!M41 -> 762.95217 | K41: =[1]Φύλλο!N41 -> 2865.2094 | L41: =[1]Φύλλο!O41 -> 571.64017 | ... S41: =[1]Φύλλο!V41 -> 1546.6569
A42: 11 | B42: ΖΩΑ | C42: =[1]Φύλλο!E42 -> 1166.4638 | D42: =[1]Φύλλο!F42 -> 50.828977 | E42: =[1]Φύλλο!H42 -> 165.09715 | F42: =[1]Φύλλο!I42 -> 20.632451 | G42: =[1]Φύλλο!J42 -> 18.404205 | H42: =[1]Φύλλο!K42 -> 126.06049 | I42: =[1]Φύλλο!L42 -> 565.39354 | J42: =[1]Φύλλο!M42 -> 60.908111 | K42: =[1]Φύλλο!N42 -> 197.11523 | L42: =[1]Φύλλο!O42 -> 31.330273 | ... S42: =[1]Φύλλο!V42 -> 52.741353
A43: 11.1 | B43: Βοοειδή | C43: =[1]Φύλλο!E43 -> 171.2737 | D43: =[1]Φύλλο!F43 -> 0.87237027 | E43: =[1]Φύλλο!H43 -> 6.1467104 | F43: =[1]Φύλλο!I43 -> 1.7502741 | G43: =[1]Φύλλο!J43 -> 3.5619711 | H43: =[1]Φύλλο!K43 -> 0.83446518 | I43: =[1]Φύλλο!L43 -> 95.637014 | J43: =[1]Φύλλο!M43 -> 23.310796 | K43: =[1]Φύλλο!N43 -> 39.831048 | L43: =[1]Φύλλο!O43 -> 10.955676 | ... S43: =[1]Φύλλο!V43 -> 4.5726811
A44: 11.2 | B44: Χοιροειδή | C44: =[1]Φύλλο!E44 -> 190.16212 | D44: =[1]Φύλλο!F44 -> 1.6380816 | E44: =[1]Φύλλο!H44 -> 12.471617 | F44: =[1]Φύλλο!I44 -> 0.64677419 | G44: =[1]Φύλλο!J44 -> 1.0815487 | H44: =[1]Φύλλο!K44 -> 10.743294 | I44: =[1]Φύλλο!L44 -> 79.826643 | J44: =[1]Φύλλο!M44 -> 7.4585106 | K44: =[1]Φύλλο!N44 -> 32.122131 | L44: =[1]Φύλλο!O44 -> 3.0013986 | ... S44: =[1]Φύλλο!V44 -> 15.138718
A45: 11.3 | B45: Ιπποειδή | C45: =[1]Φύλλο!E45 -> 0.30349 | D45: =[1]Φύλλο!F45 -> 0.00041259079 | E45: =[1]Φύλλο!H45 -> 0.036366931 | F45: =[1]Φύλλο!I45 -> 0.017505638 | G45: =[1]Φύλλο!J45 -> 0.012495607 | H45: =[1]Φύλλο!K45 -> 0.0063656865 | I45: =[1]Φύλλο!L45 -> 0.20405562 | J45: =[1]Φύλλο!M45 -> 0.076741888 | K45: =[1]Φύλλο!N45 -> 0.0825771 | L45: =[1]Φύλλο!O45 -> 0.0097253544 | ... S45: =[1]Φύλλο!V45 -> 0.001414597
A46: 11.4 | B46: Αιγοπρόβατα | C46: =[1]Φύλλο!E46 -> 366.2335 | D46: =[1]Φύλλο!F46 -> 2.8823574 | E46: =[1]Φύλλο!H46 -> 127.03108 | F46: =[1]Φύλλο!I46 -> 15.946811 | G46: =[1]Φύλλο!J46 -> 9.9115931 | H46: =[1]Φύλλο!K46 -> 101.17268 | I46: =[1]Φύλλο!L46 -> 84.690362 | J46: =[1]Φύλλο!M46 -> 21.185766 | K46: =[1]Φύλλο!N46 -> 30.688123 | L46: =[1]Φύλλο!O46 -> 15.173666 | ... S46: =[1]Φύλλο!V46 -> 20.604144
A47: 11.5 | B47: Πουλερικά | C47: =[1]Φύλλο!E47 -> 428.805 | D47: =[1]Φύλλο!F47 -> 45.435755 | E47: =[1]Φύλλο!H47 -> 12.090175 | F47: =[1]Φύλλο!I47 -> 2.1318173 | G47: =[1]Φύλλο!J47 -> 3.4630357 | H47: =[1]Φύλλο!K47 -> 6.4953221 | I47: =[1]Φύλλο!L47 -> 304.52174 | J47: =[1]Φύλλο!M47 -> 8.7609808 | K47: =[1]Φύλλο!N47 -> 94.094001 | L47: =[1]Φύλλο!O47 -> 2.1573067 | ... S47: =[1]Φύλλο!V47 -> 12.291267
A48: 11.9 | B48: Άλλα ζώα | C48: =[1]Φύλλο!E48 -> 9.6859377 | D48: =[1]Φύλλο!F48 -> 0 | E48: =[1]Φύλλο!H48 -> 7.3211963 | F48: =[1]Φύλλο!I48 -> 0.13926954 | G48: =[1]Φύλλο!J48 -> 0.37356072 | H48: =[1]Φύλλο!K48 -> 6.808366 | I48: =[1]Φύλλο!L48 -> 0.51372596 | J48: =[1]Φύλλο!M48 -> 0.11531579 | K48: =[1]Φύλλο!N48 -> 0.2973489 | L48: =[1]Φύλλο!O48 -> 0.032501343 | ... S48: =[1]Φύλλο!V48 -> 0.13312755
...
